Workbook

Sheet Leyenda
A1: Evaluación de trabajos de grado – Capítulos 1 y 2
A2: MI131 Metodología de Investigación · Administración Deportiva · Universidad Distrital · Segundo corte (carpeta 19 07102026) · Evaluación realizada el 19/10/2026
A4: Propósito | B4: Evaluar los 11 documentos (G1 – G11) en los ítems: descripción del problema, pregunta problema, objetivo general, objetivos específicos, justificación, antecedentes y marco teórico (capítulo 2), más redacción y normas APA 7.ª edición como criterio transversal. Se entregan análisis cuantitativo y cualitativo, con los errores de elaboración por ítem.
A5: Cómo se calcula | B5: Cada uno de los 31 indicadores se codifica 0 (no cumple), 1 (cumple parcialmente) o 2 (cumple). Nota del ítem = Σ(peso del indicador × código / 2) × 5. Nota total = Σ(peso del ítem × nota del ítem). Los pesos y parámetros están en la hoja Rúbrica; al modificarlos, todas las hojas se recalculan.
A6: Escala y niveles | B6: Escala 0 – 5. Umbral de logro y puntos de corte de los niveles (Alto, Satisfactorio, En desarrollo, Insuficiente) en la hoja Rúbrica, celdas D5 – D8.
A7: Código de colores | B7: Azul sobre fondo amarillo: dato de entrada o juicio del evaluador (editable). Negro: fórmula. Verde: enlace a otra hoja. Rojo / amarillo / verde en celdas: condiciones por debajo del umbral, intermedias o logradas.
A8: Orden de las hojas | B8: Leyenda · Rúbrica · Calificación (31 indicadores × 11 grupos) · Análisis cuantitativo · Análisis cualitativo (88 celdas grupo × ítem) · Errores APA y redacción · Coherencia interna · Resumen por grupo · Declaración de IA.
A9: Supuestos | B9: Se evaluó únicamente el texto entregado en cada archivo .docx. No se evaluó la metodología del capítulo 3 ni los instrumentos, salvo cuando el capítulo 2 o los objetivos remiten a ellos para comprobar la coherencia. Los pesos de la rúbrica son una propuesta del evaluador y pueden ajustarse a la rúbrica oficial del curso.
A10: Límites de la verificación | B10: La correspondencia entre citas y referencias se revisó con un script y lectura manual. Solo se consultaron en línea las referencias señaladas en la hoja Declaración de IA; las demás no se contrastaron con la fuente original. No se utilizó software de similitud: las observaciones de originalidad son indicios por revisar con la herramienta institucional.
A11: Uso de las notas | B11: Las notas son una propuesta de calificación sujeta a validación del profesor. Los comentarios son aptos para devolverlos a los estudiantes: están redactados en términos verificables, con ubicación y ejemplo del error.
A13: Resultados clave
A14: Grupos evaluados | B14: =COUNTA('Resumen por grupo'!A5:A15) -> 11
A15: Nota media del curso (0 – 5) | B15: ='Análisis cuantitativo'!D27 -> 3.3860227
A16: Grupos que alcanzan el umbral | B16: ='Análisis cuantitativo'!I27 -> 8
A17: Mayor nota (grupo) | B17: ='Análisis cuantitativo'!K27 -> G7
A18: Menor nota (grupo) | B18: ='Análisis cuantitativo'!L27 -> G5
A19: Hallazgos APA / redacción registrados | B19: ='Errores APA y redacción'!M14 -> 104
A20: Controles de la hoja de cálculo | B20: =IF(AND(Rúbrica!C19=1,Calificación!E47>=0,'Errores APA y redacción'!M21="OK"),"OK","REVISAR") -> OK

Sheet Rúbrica
A1: Rúbrica de evaluación – Capítulos 1 y 2 de la monografía
A2: Escala de cada indicador: 0 = ausente o con error grave; 1 = cumple parcialmente; 2 = cumple. Los pesos (azul) son parámetros editables.
A4: Parámetros
A5: Escala máxima de nota | D5: 5
A6: Umbral de logro (nota mínima) | D6: 3
A7: Nivel «Alto» desde | D7: 4
A8: Nivel «En desarrollo» desde | D8: 2
A10: Código | B10: Ítem evaluado | C10: Peso del ítem
A11: P | B11: Descripción del problema | C11: 0.18
A12: Q | B12: Pregunta problema | C12: 0.14
A13: OG | B13: Objetivo general | C13: 0.09
A14: OE | B14: Objetivos específicos | C14: 0.09
A15: J | B15: Justificación | C15: 0.13
A16: A | B16: Antecedentes (Capítulo 2) | C16: 0.14
A17: M | B17: Marco teórico y conceptual (Capítulo 2) | C17: 0.13
A18: T | B18: APA 7 y redacción (transversal) | C18: 0.1
B19: Suma de pesos (debe ser 100 %) | C19: =SUM(C11:C18) -> 1
A21: Indicadores
A22: Ítem | B22: Código | C22: Indicador (criterio de cumplimiento pleno = 2) | D22: Peso en el ítem | E22: Peso global | F22: Suma de pesos del ítem | G22: Verificación
A23: P | B23: P1 | C23: Contextualiza el problema en los niveles internacional, nacional y local con fuentes verificables | D23: 0.25 | E23: =SUMIF($A$11:$A$18,A23,$C$11:$C$18)*D23 -> 0.045 | F23: =SUM(D23:D27) -> 1 | G23: =IF(ROUND(F23,4)=1,"OK","Revisar") -> OK
A24: P | B24: P2 | C24: Presenta la magnitud con datos cuantitativos verificables y atribuidos correctamente a la fuente | D24: 0.25 | E24: =SUMIF($A$11:$A$18,A24,$C$11:$C$18)*D24 -> 0.045
A25: P | B25: P3 | C25: Describe causas y consecuencias, con sustento, y quiénes resultan afectados | D25: 0.2 | E25: =SUMIF($A$11:$A$18,A25,$C$11:$C$18)*D25 -> 0.036
A26: P | B26: P4 | C26: Delimita el vacío o la brecha de conocimiento que origina el estudio | D26: 0.15 | E26: =SUMIF($A$11:$A$18,A26,$C$11:$C$18)*D26 -> 0.027
A27: P | B27: P5 | C27: Redacción: claridad, registro académico, coherencia y ausencia de redundancias | D27: 0.15 | E27: =SUMIF($A$11:$A$18,A27,$C$11:$C$18)*D27 -> 0.027
A28: Q | B28: Q1 | C28: Se formula como interrogante único, claro y abierto, sin respuesta sí/no ni valorativa | D28: 0.3 | E28: =SUMIF($A$11:$A$18,A28,$C$11:$C$18)*D28 -> 0.042 | F28: =SUM(D28:D31) -> 1 | G28: =IF(ROUND(F28,4)=1,"OK","Revisar") -> OK
A29: Q | B29: Q2 | C29: Delimita objeto, población, lugar y tiempo | D29: 0.3 | E29: =SUMIF($A$11:$A$18,A29,$C$11:$C$18)*D29 -> 0.042
A30: Q | B30: Q3 | C30: Es coherente con el problema planteado (responde al vacío enunciado) | D30: 0.2 | E30: =SUMIF($A$11:$A$18,A30,$C$11:$C$18)*D30 -> 0.028
A31: Q | B31: Q4 | C31: Es investigable y viable con los recursos y datos disponibles | D31: 0.2 | E31: =SUMIF($A$11:$A$18,A31,$C$11:$C$18)*D31 -> 0.028
A32: OG | B32: G1 | C32: Verbo en infinitivo, medible, un solo propósito, sin incluir método | D32: 0.35 | E32: =SUMIF($A$11:$A$18,A32,$C$11:$C$18)*D32 -> 0.0315 | F32: =SUM(D32:D34) -> 1 | G32: =IF(ROUND(F32,4)=1,"OK","Revisar") -> OK
A33: OG | B33: G2 | C33: Responde a la pregunta problema (misma población, variables y alcance) | D33: 0.35 | E33: =SUMIF($A$11:$A$18,A33,$C$11:$C$18)*D33 -> 0.0315
A34: OG | B34: G3 | C34: Incluye la delimitación (población, contexto, periodo) | D34: 0.3 | E34: =SUMIF($A$11:$A$18,A34,$C$11:$C$18)*D34 -> 0.027
A35: OE | B35: E1 | C35: Verbos en infinitivo y medibles; un resultado de conocimiento por objetivo (no pasos del procedimiento) | D35: 0.3 | E35: =SUMIF($A$11:$A$18,A35,$C$11:$C$18)*D35 -> 0.027 | F35: =SUM(D35:D37) -> 1 | G35: =IF(ROUND(F35,4)=1,"OK","Revisar") -> OK
A36: OE | B36: E2 | C36: Derivan del objetivo general y lo cubren sin exceder su alcance | D36: 0.35 | E36: =SUMIF($A$11:$A$18,A36,$C$11:$C$18)*D36 -> 0.0315
A37: OE | B37: E3 | C37: Secuencia lógica y alcance viable para una monografía | D37: 0.35 | E37: =SUMIF($A$11:$A$18,A37,$C$11:$C$18)*D37 -> 0.0315
A38: J | B38: J1 | C38: Justificación académica o teórica vinculada con el vacío de conocimiento | D38: 0.25 | E38: =SUMIF($A$11:$A$18,A38,$C$11:$C$18)*D38 -> 0.0325 | F38: =SUM(D38:D41) -> 1 | G38: =IF(ROUND(F38,4)=1,"OK","Revisar") -> OK
A39: J | B39: J2 | C39: Justificación social y práctica para la gestión deportiva, con destinatarios identificados | D39: 0.25 | E39: =SUMIF($A$11:$A$18,A39,$C$11:$C$18)*D39 -> 0.0325
A40: J | B40: J3 | C40: Pertinencia y viabilidad del estudio (acceso, tiempo, recursos) | D40: 0.25 | E40: =SUMIF($A$11:$A$18,A40,$C$11:$C$18)*D40 -> 0.0325
A41: J | B41: J4 | C41: Sustento con fuentes y redacción sin afirmaciones no respaldadas | D41: 0.25 | E41: =SUMIF($A$11:$A$18,A41,$C$11:$C$18)*D41 -> 0.0325
A42: A | B42: A1 | C42: Pertinencia, actualidad y calidad de las fuentes | D42: 0.3 | E42: =SUMIF($A$11:$A$18,A42,$C$11:$C$18)*D42 -> 0.042 | F42: =SUM(D42:D45) -> 1 | G42: =IF(ROUND(F42,4)=1,"OK","Revisar") -> OK
A43: A | B43: A2 | C43: Estructura de la reseña: objetivo, método, resultados y aporte al estudio | D43: 0.25 | E43: =SUMIF($A$11:$A$18,A43,$C$11:$C$18)*D43 -> 0.035
...

Sheet Calificación
A1: Calificación por indicador (0 – 1 – 2) y nota por ítem
A2: Celdas azules = códigos asignados por el evaluador. Las notas por ítem y la nota total se calculan con fórmulas a partir de los pesos de la hoja Rúbrica.
A4: Ítem | B4: Código | C4: Indicador | D4: Peso en el ítem | E4: G1 | F4: G2 | G4: G3 | H4: G4 | I4: G5 | J4: G6 | K4: G7 | L4: G8 | M4: G9 | N4: G10 | O4: G11
A5: P | B5: P1 | C5: Contextualiza el problema en los niveles internacional, nacional y local con fuentes verificables | D5: =Rúbrica!D23 -> 0.25 | E5: 1 | F5: 2 | G5: 2 | H5: 1 | I5: 1 | J5: 2 | K5: 2 | L5: 2 | M5: 1 | N5: 1 | O5: 1
A6: P | B6: P2 | C6: Presenta la magnitud con datos cuantitativos verificables y atribuidos correctamente a la fuente | D6: =Rúbrica!D24 -> 0.25 | E6: 1 | F6: 1 | G6: 1 | H6: 1 | I6: 1 | J6: 1 | K6: 1 | L6: 2 | M6: 0 | N6: 0 | O6: 0
A7: P | B7: P3 | C7: Describe causas y consecuencias, con sustento, y quiénes resultan afectados | D7: =Rúbrica!D25 -> 0.2 | E7: 0 | F7: 1 | G7: 1 | H7: 1 | I7: 1 | J7: 1 | K7: 1 | L7: 2 | M7: 0 | N7: 0 | O7: 0
A8: P | B8: P4 | C8: Delimita el vacío o la brecha de conocimiento que origina el estudio | D8: =Rúbrica!D26 -> 0.15 | E8: 1 | F8: 2 | G8: 2 | H8: 1 | I8: 0 | J8: 2 | K8: 2 | L8: 2 | M8: 1 | N8: 2 | O8: 1
A9: P | B9: P5 | C9: Redacción: claridad, registro académico, coherencia y ausencia de redundancias | D9: =Rúbrica!D27 -> 0.15 | E9: 1 | F9: 1 | G9: 2 | H9: 1 | I9: 1 | J9: 2 | K9: 2 | L9: 2 | M9: 1 | N9: 2 | O9: 1
A10: Q | B10: Q1 | C10: Se formula como interrogante único, claro y abierto, sin respuesta sí/no ni valorativa | D10: =Rúbrica!D28 -> 0.3 | E10: 1 | F10: 1 | G10: 2 | H10: 2 | I10: 2 | J10: 2 | K10: 2 | L10: 2 | M10: 2 | N10: 2 | O10: 2
A11: Q | B11: Q2 | C11: Delimita objeto, población, lugar y tiempo | D11: =Rúbrica!D29 -> 0.3 | E11: 1 | F11: 2 | G11: 2 | H11: 2 | I11: 1 | J11: 2 | K11: 2 | L11: 2 | M11: 2 | N11: 1 | O11: 2
A12: Q | B12: Q3 | C12: Es coherente con el problema planteado (responde al vacío enunciado) | D12: =Rúbrica!D30 -> 0.2 | E12: 1 | F12: 1 | G12: 2 | H12: 2 | I12: 1 | J12: 2 | K12: 2 | L12: 2 | M12: 2 | N12: 2 | O12: 1
A13: Q | B13: Q4 | C13: Es investigable y viable con los recursos y datos disponibles | D13: =Rúbrica!D31 -> 0.2 | E13: 1 | F13: 1 | G13: 2 | H13: 2 | I13: 1 | J13: 2 | K13: 2 | L13: 1 | M13: 1 | N13: 2 | O13: 2
A14: OG | B14: G1 | C14: Verbo en infinitivo, medible, un solo propósito, sin incluir método | D14: =Rúbrica!D32 -> 0.35 | E14: 1 | F14: 2 | G14: 2 | H14: 2 | I14: 2 | J14: 2 | K14: 2 | L14: 1 | M14: 1 | N14: 2 | O14: 2
A15: OG | B15: G2 | C15: Responde a la pregunta problema (misma población, variables y alcance) | D15: =Rúbrica!D33 -> 0.35 | E15: 0 | F15: 2 | G15: 2 | H15: 2 | I15: 2 | J15: 2 | K15: 2 | L15: 2 | M15: 1 | N15: 2 | O15: 2
A16: OG | B16: G3 | C16: Incluye la delimitación (población, contexto, periodo) | D16: =Rúbrica!D34 -> 0.3 | E16: 1 | F16: 2 | G16: 2 | H16: 2 | I16: 2 | J16: 2 | K16: 2 | L16: 2 | M16: 2 | N16: 2 | O16: 2
... A35: T | B35: T4 | C35: Ortografía, estilo, plantilla institucional y declaración de uso de IA | D35: =Rúbrica!D53 -> 0.2 | E35: 0 | F35: 0 | G35: 1 | H35: 1 | I35: 0 | J35: 1 | K35: 1 | L35: 1 | M35: 0 | N35: 1 | O35: 1
A37: Nota por ítem (0 – 5)
A38: Ítem | B38: Código | C38: Nombre | D38: Peso del ítem | E38: G1 | F38: G2 | G38: G3 | H38: G4 | I38: G5 | J38: G6 | K38: G7 | L38: G8 | M38: G9 | N38: G10 | O38: G11
A39: P | B39: P | C39: Descripción del problema | D39: =Rúbrica!C11 -> 0.18 | E39: =SUMPRODUCT($D$5:$D$9,E$5:E$9)/2*Rúbrica!$D$5 -> 2 | F39: =SUMPRODUCT($D$5:$D$9,F$5:F$9)/2*Rúbrica!$D$5 -> 3.5 | G39: =SUMPRODUCT($D$5:$D$9,G$5:G$9)/2*Rúbrica!$D$5 -> 3.875 | H39: =SUMPRODUCT($D$5:$D$9,H$5:H$9)/2*Rúbrica!$D$5 -> 2.5 | I39: =SUMPRODUCT($D$5:$D$9,I$5:I$9)/2*Rúbrica!$D$5 -> 2.125 | J39: =SUMPRODUCT($D$5:$D$9,J$5:J$9)/2*Rúbrica!$D$5 -> 3.875 | K39: =SUMPRODUCT($D$5:$D$9,K$5:K$9)/2*Rúbrica!$D$5 -> 3.875 | L39: =SUMPRODUCT($D$5:$D$9,L$5:L$9)/2*Rúbrica!$D$5 -> 5 | ... O39: =SUMPRODUCT($D$5:$D$9,O$5:O$9)/2*Rúbrica!$D$5 -> 1.375
A40: Q | B40: Q | C40: Pregunta problema | D40: =Rúbrica!C12 -> 0.14 | E40: =SUMPRODUCT($D$10:$D$13,E$10:E$13)/2*Rúbrica!$D$5 -> 2.5 | F40: =SUMPRODUCT($D$10:$D$13,F$10:F$13)/2*Rúbrica!$D$5 -> 3.25 | G40: =SUMPRODUCT($D$10:$D$13,G$10:G$13)/2*Rúbrica!$D$5 -> 5 | H40: =SUMPRODUCT($D$10:$D$13,H$10:H$13)/2*Rúbrica!$D$5 -> 5 | I40: =SUMPRODUCT($D$10:$D$13,I$10:I$13)/2*Rúbrica!$D$5 -> 3.25 | J40: =SUMPRODUCT($D$10:$D$13,J$10:J$13)/2*Rúbrica!$D$5 -> 5 | K40: =SUMPRODUCT($D$10:$D$13,K$10:K$13)/2*Rúbrica!$D$5 -> 5 | L40: =SUMPRODUCT($D$10:$D$13,L$10:L$13)/2*Rúbrica!$D$5 -> 4.5 | ... O40: =SUMPRODUCT($D$10:$D$13,O$10:O$13)/2*Rúbrica!$D$5 -> 4.5
A41: OG | B41: OG | C41: Objetivo general | D41: =Rúbrica!C13 -> 0.09 | E41: =SUMPRODUCT($D$14:$D$16,E$14:E$16)/2*Rúbrica!$D$5 -> 1.625 | F41: =SUMPRODUCT($D$14:$D$16,F$14:F$16)/2*Rúbrica!$D$5 -> 5 | G41: =SUMPRODUCT($D$14:$D$16,G$14:G$16)/2*Rúbrica!$D$5 -> 5 | H41: =SUMPRODUCT($D$14:$D$16,H$14:H$16)/2*Rúbrica!$D$5 -> 5 | I41: =SUMPRODUCT($D$14:$D$16,I$14:I$16)/2*Rúbrica!$D$5 -> 5 | J41: =SUMPRODUCT($D$14:$D$16,J$14:J$16)/2*Rúbrica!$D$5 -> 5 | K41: =SUMPRODUCT($D$14:$D$16,K$14:K$16)/2*Rúbrica!$D$5 -> 5 | L41: =SUMPRODUCT($D$14:$D$16,L$14:L$16)/2*Rúbrica!$D$5 -> 4.125 | ... O41: =SUMPRODUCT($D$14:$D$16,O$14:O$16)/2*Rúbrica!$D$5 -> 5
A42: OE | B42: OE | C42: Objetivos específicos | D42: =Rúbrica!C14 -> 0.09 | E42: =SUMPRODUCT($D$17:$D$19,E$17:E$19)/2*Rúbrica!$D$5 -> 3.375 | F42: =SUMPRODUCT($D$17:$D$19,F$17:F$19)/2*Rúbrica!$D$5 -> 1.625 | G42: =SUMPRODUCT($D$17:$D$19,G$17:G$19)/2*Rúbrica!$D$5 -> 3.375 | H42: =SUMPRODUCT($D$17:$D$19,H$17:H$19)/2*Rúbrica!$D$5 -> 3.25 | I42: =SUMPRODUCT($D$17:$D$19,I$17:I$19)/2*Rúbrica!$D$5 -> 2.5 | J42: =SUMPRODUCT($D$17:$D$19,J$17:J$19)/2*Rúbrica!$D$5 -> 3.375 | K42: =SUMPRODUCT($D$17:$D$19,K$17:K$19)/2*Rúbrica!$D$5 -> 5 | L42: =SUMPRODUCT($D$17:$D$19,L$17:L$19)/2*Rúbrica!$D$5 -> 3.25 | ... O42: =SUMPRODUCT($D$17:$D$19,O$17:O$19)/2*Rúbrica!$D$5 -> 3.375
A43: J | B43: J | C43: Justificación | D43: =Rúbrica!C15 -> 0.13 | E43: =SUMPRODUCT($D$20:$D$23,E$20:E$23)/2*Rúbrica!$D$5 -> 1.875 | F43: =SUMPRODUCT($D$20:$D$23,F$20:F$23)/2*Rúbrica!$D$5 -> 2.5 | G43: =SUMPRODUCT($D$20:$D$23,G$20:G$23)/2*Rúbrica!$D$5 -> 4.375 | H43: =SUMPRODUCT($D$20:$D$23,H$20:H$23)/2*Rúbrica!$D$5 -> 3.125 | I43: =SUMPRODUCT($D$20:$D$23,I$20:I$23)/2*Rúbrica!$D$5 -> 1.875 | J43: =SUMPRODUCT($D$20:$D$23,J$20:J$23)/2*Rúbrica!$D$5 -> 2.5 | K43: =SUMPRODUCT($D$20:$D$23,K$20:K$23)/2*Rúbrica!$D$5 -> 4.375 | L43: =SUMPRODUCT($D$20:$D$23,L$20:L$23)/2*Rúbrica!$D$5 -> 5 | ... O43: =SUMPRODUCT($D$20:$D$23,O$20:O$23)/2*Rúbrica!$D$5 -> 3.125
A44: A | B44: A | C44: Antecedentes (Capítulo 2) | D44: =Rúbrica!C16 -> 0.14 | E44: =SUMPRODUCT($D$24:$D$27,E$24:E$27)/2*Rúbrica!$D$5 -> 3.125 | F44: =SUMPRODUCT($D$24:$D$27,F$24:F$27)/2*Rúbrica!$D$5 -> 3.625 | G44: =SUMPRODUCT($D$24:$D$27,G$24:G$27)/2*Rúbrica!$D$5 -> 4.25 | H44: =SUMPRODUCT($D$24:$D$27,H$24:H$27)/2*Rúbrica!$D$5 -> 3.875 | I44: =SUMPRODUCT($D$24:$D$27,I$24:I$27)/2*Rúbrica!$D$5 -> 1.75 | J44: =SUMPRODUCT($D$24:$D$27,J$24:J$27)/2*Rúbrica!$D$5 -> 4.625 | K44: =SUMPRODUCT($D$24:$D$27,K$24:K$27)/2*Rúbrica!$D$5 -> 4.625 | L44: =SUMPRODUCT($D$24:$D$27,L$24:L$27)/2*Rúbrica!$D$5 -> 3.875 | ... O44: =SUMPRODUCT($D$24:$D$27,O$24:O$27)/2*Rúbrica!$D$5 -> 3.875
A45: M | B45: M | C45: Marco teórico y conceptual (Capítulo 2) | D45: =Rúbrica!C17 -> 0.13 | E45: =SUMPRODUCT($D$28:$D$31,E$28:E$31)/2*Rúbrica!$D$5 -> 3 | F45: =SUMPRODUCT($D$28:$D$31,F$28:F$31)/2*Rúbrica!$D$5 -> 2.5 | G45: =SUMPRODUCT($D$28:$D$31,G$28:G$31)/2*Rúbrica!$D$5 -> 1.875 | H45: =SUMPRODUCT($D$28:$D$31,H$28:H$31)/2*Rúbrica!$D$5 -> 3.875 | I45: =SUMPRODUCT($D$28:$D$31,I$28:I$31)/2*Rúbrica!$D$5 -> 0.625 | J45: =SUMPRODUCT($D$28:$D$31,J$28:J$31)/2*Rúbrica!$D$5 -> 5 | K45: =SUMPRODUCT($D$28:$D$31,K$28:K$31)/2*Rúbrica!$D$5 -> 4.375 | L45: =SUMPRODUCT($D$28:$D$31,L$28:L$31)/2*Rúbrica!$D$5 -> 5 | ... O45: =SUMPRODUCT($D$28:$D$31,O$28:O$31)/2*Rúbrica!$D$5 -> 4.5
A46: T | B46: T | C46: APA 7 y redacción (transversal) | D46: =Rúbrica!C18 -> 0.1 | E46: =SUMPRODUCT($D$32:$D$35,E$32:E$35)/2*Rúbrica!$D$5 -> 1.25 | F46: =SUMPRODUCT($D$32:$D$35,F$32:F$35)/2*Rúbrica!$D$5 -> 2 | G46: =SUMPRODUCT($D$32:$D$35,G$32:G$35)/2*Rúbrica!$D$5 -> 1.125 | H46: =SUMPRODUCT($D$32:$D$35,H$32:H$35)/2*Rúbrica!$D$5 -> 2.5 | I46: =SUMPRODUCT($D$32:$D$35,I$32:I$35)/2*Rúbrica!$D$5 -> 0.625 | J46: =SUMPRODUCT($D$32:$D$35,J$32:J$35)/2*Rúbrica!$D$5 -> 4.5 | K46: =SUMPRODUCT($D$32:$D$35,K$32:K$35)/2*Rúbrica!$D$5 -> 3.125 | L46: =SUMPRODUCT($D$32:$D$35,L$32:L$35)/2*Rúbrica!$D$5 -> 3.25 | ... O46: =SUMPRODUCT($D$32:$D$35,O$32:O$35)/2*Rúbrica!$D$5 -> 3.75
A47: Total | C47: Nota total (0 – 5) | D47: =SUM(D39:D46) -> 1 | E47: =SUMPRODUCT($D$39:$D$46,E39:E46) -> 2.35625 | F47: =SUMPRODUCT($D$39:$D$46,F39:F46) -> 3.03875 | G47: =SUMPRODUCT($D$39:$D$46,G39:G46) -> 3.67125 | H47: =SUMPRODUCT($D$39:$D$46,H39:H46) -> 3.595 | I47: =SUMPRODUCT($D$39:$D$46,I39:I46) -> 2.145 | J47: =SUMPRODUCT($D$39:$D$46,J39:J46) -> 4.22375 | K47: =SUMPRODUCT($D$39:$D$46,K39:K46) -> 4.395 | L47: =SUMPRODUCT($D$39:$D$46,L39:L46) -> 4.36125 | ... O47: =SUMPRODUCT($D$39:$D$46,O39:O46) -> 3.54
C48: Nivel de desempeño | E48: =IF(E47>=Rúbrica!$D$7,"Alto",IF(E47>=Rúbrica!$D$6,"Satisfactorio",IF(E47>=Rúbrica!$D$8,"En desarrollo","Insuficiente"))) -> En desarrollo | F48: =IF(F47>=Rúbrica!$D$7,"Alto",IF(F47>=Rúbrica!$D$6,"Satisfactorio",IF(F47>=Rúbrica!$D$8,"En desarrollo","Insuficiente"))) -> Satisfactorio | G48: =IF(G47>=Rúbrica!$D$7,"Alto",IF(G47>=Rúbrica!$D$6,"Satisfactorio",IF(G47>=Rúbrica!$D$8,"En desarrollo","Insuficiente"))) -> Satisfactorio | H48: =IF(H47>=Rúbrica!$D$7,"Alto",IF(H47>=Rúbrica!$D$6,"Satisfactorio",IF(H47>=Rúbrica!$D$8,"En desarrollo","Insuficiente"))) -> Satisfactorio | I48: =IF(I47>=Rúbrica!$D$7,"Alto",IF(I47>=Rúbrica!$D$6,"Satisfactorio",IF(I47>=Rúbrica!$D$8,"En desarrollo","Insuficiente"))) -> En desarrollo | J48: =IF(J47>=Rúbrica!$D$7,"Alto",IF(J47>=Rúbrica!$D$6,"Satisfactorio",IF(J47>=Rúbrica!$D$8,"En desarrollo","Insuficiente"))) -> Alto | K48: =IF(K47>=Rúbrica!$D$7,"Alto",IF(K47>=Rúbrica!$D$6,"Satisfactorio",IF(K47>=Rúbrica!$D$8,"En desarrollo","Insuficiente"))) -> Alto | L48: =IF(L47>=Rúbrica!$D$7,"Alto",IF(L47>=Rúbrica!$D$6,"Satisfactorio",IF(L47>=Rúbrica!$D$8,"En desarrollo","Insuficiente"))) -> Alto | ... O48: =IF(O47>=Rúbrica!$D$7,"Alto",IF(O47>=Rúbrica!$D$6,"Satisfactorio",IF(O47>=Rúbrica!$D$8,"En desarrollo","Insuficiente"))) -> Satisfactorio
C49: ¿Alcanza el umbral de logro? | E49: =IF(E47>=Rúbrica!$D$6,"Sí","No") -> No | F49: =IF(F47>=Rúbrica!$D$6,"Sí","No") -> Sí | G49: =IF(G47>=Rúbrica!$D$6,"Sí","No") -> Sí | H49: =IF(H47>=Rúbrica!$D$6,"Sí","No") -> Sí | I49: =IF(I47>=Rúbrica!$D$6,"Sí","No") -> No | J49: =IF(J47>=Rúbrica!$D$6,"Sí","No") -> Sí | K49: =IF(K47>=Rúbrica!$D$6,"Sí","No") -> Sí | L49: =IF(L47>=Rúbrica!$D$6,"Sí","No") -> Sí | ... O49: =IF(O47>=Rúbrica!$D$6,"Sí","No") -> Sí
C50: Indicadores con código 0 (de 31) | E50: =COUNTIF(E5:E35,0) -> 6 | F50: =COUNTIF(F5:F35,0) -> 3 | G50: =COUNTIF(G5:G35,0) -> 3 | H50: =COUNTIF(H5:H35,0) -> 0 | I50: =COUNTIF(I5:I35,0) -> 9 | J50: =COUNTIF(J5:J35,0) -> 0 | K50: =COUNTIF(K5:K35,0) -> 0 | L50: =COUNTIF(L5:L35,0) -> 0 | ... O50: =COUNTIF(O5:O35,0) -> 3
C51: Indicadores con código 2 (de 31) | E51: =COUNTIF(E5:E35,2) -> 4 | F51: =COUNTIF(F5:F35,2) -> 9 | G51: =COUNTIF(G5:G35,2) -> 17 | H51: =COUNTIF(H5:H35,2) -> 13 | I51: =COUNTIF(I5:I35,2) -> 4 | J51: =COUNTIF(J5:J35,2) -> 21 | K51: =COUNTIF(K5:K35,2) -> 23 | L51: =COUNTIF(L5:L35,2) -> 22 | ... O51: =COUNTIF(O5:O35,2) -> 16

Sheet Análisis cuantitativo
A1: Análisis cuantitativo
A2: Todas las cifras se calculan con fórmulas a partir de la hoja Calificación. Escala 0 – 5; el umbral de logro es el definido en la hoja Rúbrica.
A3: A. Notas por ítem y total por grupo
A4: Grupo | B4: Tema | C4: P | D4: Q | E4: OG | F4: OE | G4: J | H4: A | I4: M | J4: T | K4: Total | L4: Posición | M4: Nivel | N4: ¿Alcanza umbral?
A5: G1 | B5: Percepción de género en periodismo deportivo | C5: =Calificación!E39 -> 2 | D5: =Calificación!E40 -> 2.5 | E5: =Calificación!E41 -> 1.625 | F5: =Calificación!E42 -> 3.375 | G5: =Calificación!E43 -> 1.875 | H5: =Calificación!E44 -> 3.125 | I5: =Calificación!E45 -> 3 | J5: =Calificación!E46 -> 1.25 | K5: =Calificación!E47 -> 2.35625 | L5: =RANK(K5,$K$5:$K$15,0) -> 10 | M5: =Calificación!E48 -> En desarrollo | N5: =Calificación!E49 -> No
A6: G2 | B6: Administración deportiva en escuelas de fútbol | C6: =Calificación!F39 -> 3.5 | D6: =Calificación!F40 -> 3.25 | E6: =Calificación!F41 -> 5 | F6: =Calificación!F42 -> 1.625 | G6: =Calificación!F43 -> 2.5 | H6: =Calificación!F44 -> 3.625 | I6: =Calificación!F45 -> 2.5 | J6: =Calificación!F46 -> 2 | K6: =Calificación!F47 -> 3.03875 | L6: =RANK(K6,$K$5:$K$15,0) -> 8 | M6: =Calificación!F48 -> Satisfactorio | N6: =Calificación!F49 -> Sí
A7: G3 | B7: Marketing deportivo y sostenibilidad (Patio Bonito) | C7: =Calificación!G39 -> 3.875 | D7: =Calificación!G40 -> 5 | E7: =Calificación!G41 -> 5 | F7: =Calificación!G42 -> 3.375 | G7: =Calificación!G43 -> 4.375 | H7: =Calificación!G44 -> 4.25 | I7: =Calificación!G45 -> 1.875 | J7: =Calificación!G46 -> 1.125 | K7: =Calificación!G47 -> 3.67125 | L7: =RANK(K7,$K$5:$K$15,0) -> 4 | M7: =Calificación!G48 -> Satisfactorio | N7: =Calificación!G49 -> Sí
A8: G4 | B8: Barreras logísticas en torneo de microfútbol | C8: =Calificación!H39 -> 2.5 | D8: =Calificación!H40 -> 5 | E8: =Calificación!H41 -> 5 | F8: =Calificación!H42 -> 3.25 | G8: =Calificación!H43 -> 3.125 | H8: =Calificación!H44 -> 3.875 | I8: =Calificación!H45 -> 3.875 | J8: =Calificación!H46 -> 2.5 | K8: =Calificación!H47 -> 3.595 | L8: =RANK(K8,$K$5:$K$15,0) -> 5 | M8: =Calificación!H48 -> Satisfactorio | N8: =Calificación!H49 -> Sí
A9: G5 | B9: Marketing deportivo y fútbol femenino (visibilidad) | C9: =Calificación!I39 -> 2.125 | D9: =Calificación!I40 -> 3.25 | E9: =Calificación!I41 -> 5 | F9: =Calificación!I42 -> 2.5 | G9: =Calificación!I43 -> 1.875 | H9: =Calificación!I44 -> 1.75 | I9: =Calificación!I45 -> 0.625 | J9: =Calificación!I46 -> 0.625 | K9: =Calificación!I47 -> 2.145 | L9: =RANK(K9,$K$5:$K$15,0) -> 11 | M9: =Calificación!I48 -> En desarrollo | N9: =Calificación!I49 -> No
A10: G6 | B10: Calidad del servicio del gimnasio e intención de continuar | C10: =Calificación!J39 -> 3.875 | D10: =Calificación!J40 -> 5 | E10: =Calificación!J41 -> 5 | F10: =Calificación!J42 -> 3.375 | G10: =Calificación!J43 -> 2.5 | H10: =Calificación!J44 -> 4.625 | I10: =Calificación!J45 -> 5 | J10: =Calificación!J46 -> 4.5 | K10: =Calificación!J47 -> 4.22375 | L10: =RANK(K10,$K$5:$K$15,0) -> 3 | M10: =Calificación!J48 -> Alto | N10: =Calificación!J49 -> Sí
A11: G7 | B11: Desigualdad de género en la trayectoria académica | C11: =Calificación!K39 -> 3.875 | D11: =Calificación!K40 -> 5 | E11: =Calificación!K41 -> 5 | F11: =Calificación!K42 -> 5 | G11: =Calificación!K43 -> 4.375 | H11: =Calificación!K44 -> 4.625 | I11: =Calificación!K45 -> 4.375 | J11: =Calificación!K46 -> 3.125 | K11: =Calificación!K47 -> 4.395 | L11: =RANK(K11,$K$5:$K$15,0) -> 1 | M11: =Calificación!K48 -> Alto | N11: =Calificación!K49 -> Sí
A12: G8 | B12: Economía del baloncesto femenino profesional | C12: =Calificación!L39 -> 5 | D12: =Calificación!L40 -> 4.5 | E12: =Calificación!L41 -> 4.125 | F12: =Calificación!L42 -> 3.25 | G12: =Calificación!L43 -> 5 | H12: =Calificación!L44 -> 3.875 | I12: =Calificación!L45 -> 5 | J12: =Calificación!L46 -> 3.25 | K12: =Calificación!L47 -> 4.36125 | L12: =RANK(K12,$K$5:$K$15,0) -> 2 | M12: =Calificación!L48 -> Alto | N12: =Calificación!L49 -> Sí
A13: G9 | B13: Herramientas tecnológicas de análisis táctico | C13: =Calificación!M39 -> 1.375 | D13: =Calificación!M40 -> 4.5 | E13: =Calificación!M41 -> 3.25 | F13: =Calificación!M42 -> 1.75 | G13: =Calificación!M43 -> 1.875 | H13: =Calificación!M44 -> 1.75 | I13: =Calificación!M45 -> 3.125 | J13: =Calificación!M46 -> 1.375 | K13: =Calificación!M47 -> 2.36 | L13: =RANK(K13,$K$5:$K$15,0) -> 9 | M13: =Calificación!M48 -> En desarrollo | N13: =Calificación!M49 -> No
A14: G10 | B14: Realidad virtual y competencias profesionales | C14: =Calificación!N39 -> 2.125 | D14: =Calificación!N40 -> 4.25 | E14: =Calificación!N41 -> 5 | F14: =Calificación!N42 -> 4.25 | G14: =Calificación!N43 -> 3.75 | H14: =Calificación!N44 -> 3.5 | I14: =Calificación!N45 -> 4.5 | J14: =Calificación!N46 -> 1.875 | K14: =Calificación!N47 -> 3.56 | L14: =RANK(K14,$K$5:$K$15,0) -> 6 | M14: =Calificación!N48 -> Satisfactorio | N14: =Calificación!N49 -> Sí
A15: G11 | B15: Instagram, frecuencia, formato y engagement | C15: =Calificación!O39 -> 1.375 | D15: =Calificación!O40 -> 4.5 | E15: =Calificación!O41 -> 5 | F15: =Calificación!O42 -> 3.375 | G15: =Calificación!O43 -> 3.125 | H15: =Calificación!O44 -> 3.875 | I15: =Calificación!O45 -> 4.5 | J15: =Calificación!O46 -> 3.75 | K15: =Calificación!O47 -> 3.54 | L15: =RANK(K15,$K$5:$K$15,0) -> 7 | M15: =Calificación!O48 -> Satisfactorio | N15: =Calificación!O49 -> Sí
A17: B. Estadística descriptiva por ítem (n = 11 grupos)
A18: Código | B18: Ítem | C18: Peso | D18: Media | E18: Mediana | F18: Mínimo | G18: Máximo | H18: Desv. estándar | I18: Grupos ≥ umbral | J18: % de grupos ≥ umbral | K18: Mayor nota | L18: Menor nota
A19: P | B19: Descripción del problema | C19: =Rúbrica!C11 -> 0.18 | D19: =AVERAGE(C$5:C$15) -> 2.875 | E19: =MEDIAN(C$5:C$15) -> 2.5 | F19: =MIN(C$5:C$15) -> 1.375 | G19: =MAX(C$5:C$15) -> 5 | H19: =STDEV(C$5:C$15) -> 1.2015615 | I19: =COUNTIF(C$5:C$15,">="&Rúbrica!$D$6) -> 5 | J19: =I19/COUNT(C$5:C$15) -> 0.45454545 | K19: =INDEX($A$5:$A$15,MATCH(MAX(C$5:C$15),C$5:C$15,0)) -> G8 | L19: =INDEX($A$5:$A$15,MATCH(MIN(C$5:C$15),C$5:C$15,0)) -> G9
A20: Q | B20: Pregunta problema | C20: =Rúbrica!C12 -> 0.14 | D20: =AVERAGE(D$5:D$15) -> 4.25 | E20: =MEDIAN(D$5:D$15) -> 4.5 | F20: =MIN(D$5:D$15) -> 2.5 | G20: =MAX(D$5:D$15) -> 5 | H20: =STDEV(D$5:D$15) -> 0.8660254 | I20: =COUNTIF(D$5:D$15,">="&Rúbrica!$D$6) -> 10 | J20: =I20/COUNT(D$5:D$15) -> 0.90909091 | K20: =INDEX($A$5:$A$15,MATCH(MAX(D$5:D$15),D$5:D$15,0)) -> G3 | L20: =INDEX($A$5:$A$15,MATCH(MIN(D$5:D$15),D$5:D$15,0)) -> G1
A21: OG | B21: Objetivo general | C21: =Rúbrica!C13 -> 0.09 | D21: =AVERAGE(E$5:E$15) -> 4.4545455 | E21: =MEDIAN(E$5:E$15) -> 5 | F21: =MIN(E$5:E$15) -> 1.625 | G21: =MAX(E$5:E$15) -> 5 | H21: =STDEV(E$5:E$15) -> 1.0929786 | I21: =COUNTIF(E$5:E$15,">="&Rúbrica!$D$6) -> 10 | J21: =I21/COUNT(E$5:E$15) -> 0.90909091 | K21: =INDEX($A$5:$A$15,MATCH(MAX(E$5:E$15),E$5:E$15,0)) -> G2 | L21: =INDEX($A$5:$A$15,MATCH(MIN(E$5:E$15),E$5:E$15,0)) -> G1
A22: OE | B22: Objetivos específicos | C22: =Rúbrica!C14 -> 0.09 | D22: =AVERAGE(F$5:F$15) -> 3.1931818 | E22: =MEDIAN(F$5:F$15) -> 3.375 | F22: =MIN(F$5:F$15) -> 1.625 | G22: =MAX(F$5:F$15) -> 5 | H22: =STDEV(F$5:F$15) -> 0.97686302 | I22: =COUNTIF(F$5:F$15,">="&Rúbrica!$D$6) -> 8 | J22: =I22/COUNT(F$5:F$15) -> 0.72727273 | K22: =INDEX($A$5:$A$15,MATCH(MAX(F$5:F$15),F$5:F$15,0)) -> G7 | L22: =INDEX($A$5:$A$15,MATCH(MIN(F$5:F$15),F$5:F$15,0)) -> G2
A23: J | B23: Justificación | C23: =Rúbrica!C15 -> 0.13 | D23: =AVERAGE(G$5:G$15) -> 3.125 | E23: =MEDIAN(G$5:G$15) -> 3.125 | F23: =MIN(G$5:G$15) -> 1.875 | G23: =MAX(G$5:G$15) -> 5 | H23: =STDEV(G$5:G$15) -> 1.118034 | I23: =COUNTIF(G$5:G$15,">="&Rúbrica!$D$6) -> 6 | J23: =I23/COUNT(G$5:G$15) -> 0.54545455 | K23: =INDEX($A$5:$A$15,MATCH(MAX(G$5:G$15),G$5:G$15,0)) -> G8 | L23: =INDEX($A$5:$A$15,MATCH(MIN(G$5:G$15),G$5:G$15,0)) -> G1
A24: A | B24: Antecedentes (Capítulo 2) | C24: =Rúbrica!C16 -> 0.14 | D24: =AVERAGE(H$5:H$15) -> 3.5340909 | E24: =MEDIAN(H$5:H$15) -> 3.875 | F24: =MIN(H$5:H$15) -> 1.75 | G24: =MAX(H$5:H$15) -> 4.625 | H24: =STDEV(H$5:H$15) -> 0.98914564 | I24: =COUNTIF(H$5:H$15,">="&Rúbrica!$D$6) -> 9 | J24: =I24/COUNT(H$5:H$15) -> 0.81818182 | K24: =INDEX($A$5:$A$15,MATCH(MAX(H$5:H$15),H$5:H$15,0)) -> G6 | L24: =INDEX($A$5:$A$15,MATCH(MIN(H$5:H$15),H$5:H$15,0)) -> G5
A25: M | B25: Marco teórico y conceptual (Capítulo 2) | C25: =Rúbrica!C17 -> 0.13 | D25: =AVERAGE(I$5:I$15) -> 3.4886364 | E25: =MEDIAN(I$5:I$15) -> 3.875 | F25: =MIN(I$5:I$15) -> 0.625 | G25: =MAX(I$5:I$15) -> 5 | H25: =STDEV(I$5:I$15) -> 1.4036276 | I25: =COUNTIF(I$5:I$15,">="&Rúbrica!$D$6) -> 8 | J25: =I25/COUNT(I$5:I$15) -> 0.72727273 | K25: =INDEX($A$5:$A$15,MATCH(MAX(I$5:I$15),I$5:I$15,0)) -> G6 | L25: =INDEX($A$5:$A$15,MATCH(MIN(I$5:I$15),I$5:I$15,0)) -> G5
A26: T | B26: APA 7 y redacción (transversal) | C26: =Rúbrica!C18 -> 0.1 | D26: =AVERAGE(J$5:J$15) -> 2.3068182 | E26: =MEDIAN(J$5:J$15) -> 2 | F26: =MIN(J$5:J$15) -> 0.625 | G26: =MAX(J$5:J$15) -> 4.5 | H26: =STDEV(J$5:J$15) -> 1.2239327 | I26: =COUNTIF(J$5:J$15,">="&Rúbrica!$D$6) -> 4 | J26: =I26/COUNT(J$5:J$15) -> 0.36363636 | K26: =INDEX($A$5:$A$15,MATCH(MAX(J$5:J$15),J$5:J$15,0)) -> G6 | L26: =INDEX($A$5:$A$15,MATCH(MIN(J$5:J$15),J$5:J$15,0)) -> G5
A27: Total | B27: Nota total | C27: =SUM(C19:C26) -> 1 | D27: =AVERAGE(K$5:K$15) -> 3.3860227 | E27: =MEDIAN(K$5:K$15) -> 3.56 | F27: =MIN(K$5:K$15) -> 2.145 | G27: =MAX(K$5:K$15) -> 4.395 | H27: =STDEV(K$5:K$15) -> 0.81386632 | I27: =COUNTIF(K$5:K$15,">="&Rúbrica!$D$6) -> 8 | J27: =I27/COUNT(K$5:K$15) -> 0.72727273 | K27: =INDEX($A$5:$A$15,MATCH(MAX(K$5:K$15),K$5:K$15,0)) -> G7 | L27: =INDEX($A$5:$A$15,MATCH(MIN(K$5:K$15),K$5:K$15,0)) -> G5
A30: C. Cumplimiento por indicador (n = 11 grupos)
A31: Código | B31: Indicador | C31: Grupos con 2 | D31: Grupos con 1 | E31: Grupos con 0 | F31: % con cumplimiento pleno | G31: % con código 0 | H31: Media (0 – 2) | I31: Prioridad de mejora
A32: P1 | B32: Contextualiza el problema en los niveles internacional, nacional y local con fuentes verificables | C32: =COUNTIF(Calificación!$E$5:$O$5,2) -> 5 | D32: =COUNTIF(Calificación!$E$5:$O$5,1) -> 6 | E32: =COUNTIF(Calificación!$E$5:$O$5,0) -> 0 | F32: =C32/COUNT(Calificación!$E$5:$O$5) -> 0.45454545 | G32: =E32/COUNT(Calificación!$E$5:$O$5) -> 0 | H32: =AVERAGE(Calificación!$E$5:$O$5) -> 1.4545455 | I32: =IF(G32>=0.5,"Crítica",IF(G32>=0.25,"Alta",IF(G32>0,"Media","Sin casos con 0"))) -> Sin casos con 0
A33: P2 | B33: Presenta la magnitud con datos cuantitativos verificables y atribuidos correctamente a la fuente | C33: =COUNTIF(Calificación!$E$6:$O$6,2) -> 1 | D33: =COUNTIF(Calificación!$E$6:$O$6,1) -> 7 | E33: =COUNTIF(Calificación!$E$6:$O$6,0) -> 3 | F33: =C33/COUNT(Calificación!$E$6:$O$6) -> 0.090909091 | G33: =E33/COUNT(Calificación!$E$6:$O$6) -> 0.27272727 | H33: =AVERAGE(Calificación!$E$6:$O$6) -> 0.81818182 | I33: =IF(G33>=0.5,"Crítica",IF(G33>=0.25,"Alta",IF(G33>0,"Media","Sin casos con 0"))) -> Alta
A34: P3 | B34: Describe causas y consecuencias, con sustento, y quiénes resultan afectados | C34: =COUNTIF(Calificación!$E$7:$O$7,2) -> 1 | D34: =COUNTIF(Calificación!$E$7:$O$7,1) -> 6 | E34: =COUNTIF(Calificación!$E$7:$O$7,0) -> 4 | F34: =C34/COUNT(Calificación!$E$7:$O$7) -> 0.090909091 | G34: =E34/COUNT(Calificación!$E$7:$O$7) -> 0.36363636 | H34: =AVERAGE(Calificación!$E$7:$O$7) -> 0.72727273 | I34: =IF(G34>=0.5,"Crítica",IF(G34>=0.25,"Alta",IF(G34>0,"Media","Sin casos con 0"))) -> Alta
A35: P4 | B35: Delimita el vacío o la brecha de conocimiento que origina el estudio | C35: =COUNTIF(Calificación!$E$8:$O$8,2) -> 6 | D35: =COUNTIF(Calificación!$E$8:$O$8,1) -> 4 | E35: =COUNTIF(Calificación!$E$8:$O$8,0) -> 1 | F35: =C35/COUNT(Calificación!$E$8:$O$8) -> 0.54545455 | G35: =E35/COUNT(Calificación!$E$8:$O$8) -> 0.090909091 | H35: =AVERAGE(Calificación!$E$8:$O$8) -> 1.4545455 | I35: =IF(G35>=0.5,"Crítica",IF(G35>=0.25,"Alta",IF(G35>0,"Media","Sin casos con 0"))) -> Media
A36: P5 | B36: Redacción: claridad, registro académico, coherencia y ausencia de redundancias | C36: =COUNTIF(Calificación!$E$9:$O$9,2) -> 5 | D36: =COUNTIF(Calificación!$E$9:$O$9,1) -> 6 | E36: =COUNTIF(Calificación!$E$9:$O$9,0) -> 0 | F36: =C36/COUNT(Calificación!$E$9:$O$9) -> 0.45454545 | G36: =E36/COUNT(Calificación!$E$9:$O$9) -> 0 | H36: =AVERAGE(Calificación!$E$9:$O$9) -> 1.4545455 | I36: =IF(G36>=0.5,"Crítica",IF(G36>=0.25,"Alta",IF(G36>0,"Media","Sin casos con 0"))) -> Sin casos con 0
A37: Q1 | B37: Se formula como interrogante único, claro y abierto, sin respuesta sí/no ni valorativa | C37: =COUNTIF(Calificación!$E$10:$O$10,2) -> 9 | D37: =COUNTIF(Calificación!$E$10:$O$10,1) -> 2 | E37: =COUNTIF(Calificación!$E$10:$O$10,0) -> 0 | F37: =C37/COUNT(Calificación!$E$10:$O$10) -> 0.81818182 | G37: =E37/COUNT(Calificación!$E$10:$O$10) -> 0 | H37: =AVERAGE(Calificación!$E$10:$O$10) -> 1.8181818 | I37: =IF(G37>=0.5,"Crítica",IF(G37>=0.25,"Alta",IF(G37>0,"Media","Sin casos con 0"))) -> Sin casos con 0
A38: Q2 | B38: Delimita objeto, población, lugar y tiempo | C38: =COUNTIF(Calificación!$E$11:$O$11,2) -> 8 | D38: =COUNTIF(Calificación!$E$11:$O$11,1) -> 3 | E38: =COUNTIF(Calificación!$E$11:$O$11,0) -> 0 | F38: =C38/COUNT(Calificación!$E$11:$O$11) -> 0.72727273 | G38: =E38/COUNT(Calificación!$E$11:$O$11) -> 0 | H38: =AVERAGE(Calificación!$E$11:$O$11) -> 1.7272727 | I38: =IF(G38>=0.5,"Crítica",IF(G38>=0.25,"Alta",IF(G38>0,"Media","Sin casos con 0"))) -> Sin casos con 0
A39: Q3 | B39: Es coherente con el problema planteado (responde al vacío enunciado) | C39: =COUNTIF(Calificación!$E$12:$O$12,2) -> 7 | D39: =COUNTIF(Calificación!$E$12:$O$12,1) -> 4 | E39: =COUNTIF(Calificación!$E$12:$O$12,0) -> 0 | F39: =C39/COUNT(Calificación!$E$12:$O$12) -> 0.63636364 | G39: =E39/COUNT(Calificación!$E$12:$O$12) -> 0 | H39: =AVERAGE(Calificación!$E$12:$O$12) -> 1.6363636 | I39: =IF(G39>=0.5,"Crítica",IF(G39>=0.25,"Alta",IF(G39>0,"Media","Sin casos con 0"))) -> Sin casos con 0
A40: Q4 | B40: Es investigable y viable con los recursos y datos disponibles | C40: =COUNTIF(Calificación!$E$13:$O$13,2) -> 6 | D40: =COUNTIF(Calificación!$E$13:$O$13,1) -> 5 | E40: =COUNTIF(Calificación!$E$13:$O$13,0) -> 0 | F40: =C40/COUNT(Calificación!$E$13:$O$13) -> 0.54545455 | G40: =E40/COUNT(Calificación!$E$13:$O$13) -> 0 | H40: =AVERAGE(Calificación!$E$13:$O$13) -> 1.5454545 | I40: =IF(G40>=0.5,"Crítica",IF(G40>=0.25,"Alta",IF(G40>0,"Media","Sin casos con 0"))) -> Sin casos con 0
A41: G1 | B41: Verbo en infinitivo, medible, un solo propósito, sin incluir método | C41: =COUNTIF(Calificación!$E$14:$O$14,2) -> 8 | D41: =COUNTIF(Calificación!$E$14:$O$14,1) -> 3 | E41: =COUNTIF(Calificación!$E$14:$O$14,0) -> 0 | F41: =C41/COUNT(Calificación!$E$14:$O$14) -> 0.72727273 | G41: =E41/COUNT(Calificación!$E$14:$O$14) -> 0 | H41: =AVERAGE(Calificación!$E$14:$O$14) -> 1.7272727 | I41: =IF(G41>=0.5,"Crítica",IF(G41>=0.25,"Alta",IF(G41>0,"Media","Sin casos con 0"))) -> Sin casos con 0
A42: G2 | B42: Responde a la pregunta problema (misma población, variables y alcance) | C42: =COUNTIF(Calificación!$E$15:$O$15,2) -> 9 | D42: =COUNTIF(Calificación!$E$15:$O$15,1) -> 1 | E42: =COUNTIF(Calificación!$E$15:$O$15,0) -> 1 | F42: =C42/COUNT(Calificación!$E$15:$O$15) -> 0.81818182 | G42: =E42/COUNT(Calificación!$E$15:$O$15) -> 0.090909091 | H42: =AVERAGE(Calificación!$E$15:$O$15) -> 1.7272727 | I42: =IF(G42>=0.5,"Crítica",IF(G42>=0.25,"Alta",IF(G42>0,"Media","Sin casos con 0"))) -> Media
A43: G3 | B43: Incluye la delimitación (población, contexto, periodo) | C43: =COUNTIF(Calificación!$E$16:$O$16,2) -> 10 | D43: =COUNTIF(Calificación!$E$16:$O$16,1) -> 1 | E43: =COUNTIF(Calificación!$E$16:$O$16,0) -> 0 | F43: =C43/COUNT(Calificación!$E$16:$O$16) -> 0.90909091 | G43: =E43/COUNT(Calificación!$E$16:$O$16) -> 0 | H43: =AVERAGE(Calificación!$E$16:$O$16) -> 1.9090909 | I43: =IF(G43>=0.5,"Crítica",IF(G43>=0.25,"Alta",IF(G43>0,"Media","Sin casos con 0"))) -> Sin casos con 0
...

Sheet Análisis cualitativo
A1: Análisis cualitativo por grupo e ítem
A2: Errores de elaboración identificados, con ejemplos tomados de los documentos. La nota de cada ítem se enlaza con la hoja Calificación.
A4: Grupo | B4: Ítem | C4: Nota del ítem (0 – 5) | D4: Condición | E4: Hallazgos y errores de elaboración (con ejemplos)
A5: G1 | B5: Descripción del problema | C5: =Calificación!E39 -> 2 | D5: =IF(C5>=Rúbrica!$D$6,"Logrado","No logrado") -> No logrado | E5: Contextualiza con un dato internacional (Boczek et al., 2023: 91,7 % de artículos firmados por hombres) y un antecedente nacional cualitativo (Zapata Correa et al., 2026), pero no aporta cifras colombianas ni locales (Bogotá). No se describen causas ni consecuencias de la desigualdad en el periodismo deportivo, y el vacío se enuncia como desconocimiento de la percepción de una población, no como carencia frente a la literatura. La redacción repite tres veces la salvedad «sin asumir previamente que existe una situación de desigualdad», y el planteamiento se duplica entre la Introducción y la Descripción del problema. El dato de Boczek se reporta como 8,2 % en el problema y como «8,1 %» en antecedentes.
A6: G1 | B6: Pregunta problema | C6: =Calificación!E40 -> 2.5 | D6: =IF(C6>=Rúbrica!$D$6,"Logrado","No logrado") -> No logrado | E6: Formulada como interrogante abierta y con población y periodo (segundo periodo de 2026), pero extensa y con una incisa entre guiones. Integra dos objetos: la percepción de estudiantes y la gestión de comunicaciones institucionales de clubes («como referente para…»), lo que impide delimitar la unidad de análisis. La frase que la antecede («se plantea la siguiente pregunta de investigación») carece de dos puntos.
A7: G1 | B7: Objetivo general | C7: =Calificación!E41 -> 1.625 | D7: =IF(C7>=Rúbrica!$D$6,"Logrado","No logrado") -> No logrado | E7: Verbo en infinitivo, pero «analizar la relación entre» sugiere un propósito relacional que la metodología (descriptivo-interpretativa, cualitativa) no contempla. Contiene error de redacción («relación de entre»). No responde a la pregunta: sustituye la población (estudiantes) por documentos (publicaciones y noticias). Sin delimitación temporal ni de unidades (cuántos clubes, qué medios).
A8: G1 | B8: Objetivos específicos | C8: =Calificación!E42 -> 3.375 | D8: =IF(C8>=Rúbrica!$D$6,"Logrado","No logrado") -> Logrado | E8: Los verbos (identificar, analizar, comparar) son pertinentes y secuenciales, aunque el tercero añade «con el propósito de reconocer posibles relaciones», lo que introduce un segundo propósito. Ninguno aborda las oportunidades profesionales, la visibilidad y la participación que la pregunta menciona. «genero» sin tilde.
A9: G1 | B9: Justificación | C9: =Calificación!E43 -> 1.875 | D9: =IF(C9>=Rúbrica!$D$6,"Logrado","No logrado") -> No logrado | E9: Se articula en cuatro párrafos (social, académico, profesional, delimitación) y reconoce la limitación de no generalizar. Se sustenta únicamente en dos fuentes (Boczek et al., 2023; Zapata Correa et al., 2026) que se repiten del problema. No explicita la contribución a la gestión deportiva (comunicación de clubes), no hay viabilidad (acceso a la población, tiempo, recursos) y la justificación no corresponde al objeto del objetivo general.
A10: G1 | B10: Antecedentes (Capítulo 2) | C10: =Calificación!E44 -> 3.125 | D10: =IF(C10>=Rúbrica!$D$6,"Logrado","No logrado") -> Logrado | E10: Seis estudios reseñados con estructura reconocible (objetivo, método, resultado, pertinencia) y revistas indexadas; 2016 a 2026. Faltan: encabezado y nexo en Boczek et al. (2023), cierre de síntesis, identificación del vacío y antecedentes locales o sobre estudiantes de formación deportiva (Ramon Vegas et al., 2019 está en referencias pero no se usa). Coronel Puello (2024) no figura en la lista de referencias. Afirmaciones sobredimensionadas: un estudio cualitativo con siete periodistas «demuestra la existencia de desigualdades».
A11: G1 | B11: Marco teórico y conceptual (Capítulo 2) | C11: =Calificación!E45 -> 3 | D11: =IF(C11>=Rúbrica!$D$6,"Logrado","No logrado") -> Logrado | E11: Presenta representaciones sociales, framing y perspectiva de género; las fuentes primarias (Moscovici, 1988; Antunovic y Whiteside, 2018) existen, pero Entman (1993) y Jodelet (2008) no están en las referencias y Calvo Ortega y Gutiérrez San Miguel aparece como 2017 en el texto frente a 2016 en la lista. La sección se titula «Marco conceptual» pero desarrolla teorías. No se define igualdad de género, comunicación institucional ni visibilidad, que son las categorías del instrumento. La teoría de base corresponde a la percepción de estudiantes, no al análisis de contenido.
A12: G1 | B12: APA 7 y redacción (transversal) | C12: =Calificación!E46 -> 1.25 | D12: =IF(C12>=Rúbrica!$D$6,"Logrado","No logrado") -> No logrado | E12: Referencias: 14 entradas, 8 sin cita en el texto (Bruce, 2016; Calvo-Ortega, 2020; Gómez-Colell et al., 2017; Olabe Sánchez, 2010 y 2012; Ramon Vegas et al., 2019; Sainz de Baranda Andújar, 2014a y 2014b) y 4 citas sin referencia (Coronel Puello, 2024; Entman, 1993; Jodelet, 2008; Calvo Ortega y Gutiérrez San Miguel, 2017). Cita narrativa con cuatro autores sin «et al.» (Zapata Correa, Durán-Palacio, Rodríguez Gómez y Restrepo Echavarría, 2026). Persisten textos de plantilla en el cuerpo (Dedicatoria (opcional), instrucciones del Resumen, «Figura 1 Título en cursiva», «Indicar la mejor opción…»).
A13: G2 | B13: Descripción del problema | C13: =Calificación!F39 -> 3.5 | D13: =IF(C13>=Rúbrica!$D$6,"Logrado","No logrado") -> Logrado | E13: Estructura por niveles internacional, nacional y local, con datos verificables (Sarmiento Espiau et al., 2025: n = 125; Barahona Vinasco et al., 2023: 103 ligas y clubes; 26,86 % y 41,75 %), síntesis y vacío explícito («hasta donde permitió establecer la búsqueda realizada»). Debilidades: las cifras provienen de Caldas y de Antioquia (2010), no de Bogotá; la deserción de deportistas y la ineficiencia en recursos se afirman en la Introducción sin fuente; la escuela Elizalde FC aparece sin justificar por qué es el caso de estudio. Los párrafos de nivel internacional y nacional se reproducen casi literalmente en Antecedentes. La Introducción tiene fallas graves de redacción («manejas unas de las principales ofertas», «vacíos internacionales», «se en cargan», «En conclusión» al inicio del documento).
A14: G2 | B14: Pregunta problema | C14: =Calificación!F40 -> 3.25 | D14: =IF(C14>=Rúbrica!$D$6,"Logrado","No logrado") -> Logrado | E14: Delimita sujeto, lugar (Kennedy, Bogotá) y periodo (2026-2). Sin embargo, «¿Cómo fortalecer la gestión…?» es una pregunta de intervención, no de investigación descriptiva; «fortalecer» no tiene criterio de medición y el problema describe ausencia de delimitación de funciones, no una deficiencia de gestión demostrada en la escuela.
A15: G2 | B15: Objetivo general | C15: =Calificación!F41 -> 5 | D15: =IF(C15>=Rúbrica!$D$6,"Logrado","No logrado") -> Logrado | E15: Verbo «diseñar», un solo propósito y delimitación completa (escuela, localidad, periodo). Corresponde a la pregunta, pero no al problema ni a la Introducción («analizar y definir las funciones»). El «modelo de gestión estratégica» no se define en el marco teórico.
A16: G2 | B16: Objetivos específicos | C16: =Calificación!F42 -> 1.625 | D16: =IF(C16>=Rúbrica!$D$6,"Logrado","No logrado") -> No logrado | E16: El OE1 acumula cinco objetos en una sola enunciación («conocimientos, funciones, fortalezas, limitaciones y procesos»). El OE2 supone un «diagnóstico realizado», que sería el resultado del OE1. El OE3 (evaluar la aplicación de la estrategia) requiere implementar la estrategia y medir resultados, lo que no es viable dentro del periodo 2026-2 ni está en el objetivo general. Los tres repiten la cláusula de contexto completa, lo que alarga innecesariamente la redacción.
A17: G2 | B17: Justificación | C17: =Calificación!F43 -> 2.5 | D17: =IF(C17>=Rúbrica!$D$6,"Logrado","No logrado") -> No logrado | E17: Presenta tres dimensiones (académica, profesional, social) y vincula con el problema. No contiene ninguna cita: afirmaciones como «una estructura administrativa formal es clave para optimizar la toma de decisiones» y «las deficiencias en la gestión pueden provocar la deserción» carecen de sustento y se redactan como hechos. El verbo «demuestra» no corresponde a un estudio descriptivo. No se plantea viabilidad ni el aporte específico a Elizalde FC o al programa de Administración Deportiva. El uso de «Mientras que» es inadecuado como conector.
A18: G2 | B18: Antecedentes (Capítulo 2) | C18: =Calificación!F44 -> 3.625 | D18: =IF(C18>=Rúbrica!$D$6,"Logrado","No logrado") -> Logrado | E18: Organizados por ámbitos, con síntesis y brecha explícitas (único trabajo del grupo con este cierre). Cobertura internacional (España 2025; Cuba 2024), nacional (Caldas 2023; Antioquia 2010) y distrital (Pedreros, 2016). Fuentes de 2010 y 2016 superan el rango de actualidad; el trabajo de Pedreros se describe como «trabajo de grado» en el problema y «trabajo de posgrado» en antecedentes, y no tiene enlace de repositorio. La Resolución 639 de 2021 es normativa, no antecedente investigativo. Los antecedentes de Zapata et al. (2010) y Pedreros (2016) carecen de objetivo, método y resultados. Se duplican párrafos del problema.
A19: G2 | B19: Marco teórico y conceptual (Capítulo 2) | C19: =Calificación!F45 -> 2.5 | D19: =IF(C19>=Rúbrica!$D$6,"Logrado","No logrado") -> No logrado | E19: Se limita a un marco conceptual de cinco definiciones, construidas casi en su totalidad por citas secundarias (Cardona y Padierna, 2017; García y Pradas, 2017; Pedrosa, 2016; Méndez, 2014, «como se citó en» Barahona Vinasco et al., 2023). No hay marco teórico: falta el modelo de gestión estratégica y la teoría administrativa que fundamente las funciones. Inconsistencia interna: se anuncian «cinco funciones» (planear, organizar, dirigir, ejecutar, controlar) y luego se desarrollan cuatro. «Pedrosa, 2016» difiere del autor de la lista («Pedreros, 2016»).
A20: G2 | B20: APA 7 y redacción (transversal) | C20: =Calificación!F46 -> 2 | D20: =IF(C20>=Rúbrica!$D$6,"Logrado","No logrado") -> No logrado | E20: Correspondencia cita–referencia casi completa, pero con tres fallas: «Pedrosa (2016)» vs. «Pedreros (2016)»; la Resolución 639 de 2021 se cita a través de una página del IDRD sin referencia propia; Cardona y Padierna (2017) y García y Pradas (2017) figuran en la lista como fuentes primarias mientras se citan como secundarias. Ley 181 de 1995 no sigue el formato APA 7 (falta Congreso de la República de Colombia como autor y año entre paréntesis tras el título). Faltan DOI o URL en Méndez Álvarez et al. (2024) y Pedreros (2016). Introducción con errores ortográficos y sintácticos recurrentes, portada con errores («Faculta de Medio Ambiente», «caldas»), Metodología y Resultados con texto de plantilla, y declaración de IA incompleta y mal redactada.
A21: G3 | B21: Descripción del problema | C21: =Calificación!G39 -> 3.875 | D21: =IF(C21>=Rúbrica!$D$6,"Logrado","No logrado") -> Logrado | E21: Mejor estructurado del curso en niveles internacional, nacional y local, con datos territoriales verificables (Secretaría Distrital de Planeación, 2024: 85,9 % de manzanas de estrato 1 de Kennedy en Patio Bonito; Alcaldía Local de Kennedy, 2026: más de 2.000 cupos gratuitos) y vacío explícito. Debilidades: no se aporta ninguna cifra sobre las escuelas (número en Patio Bonito, ingresos, deserción, cierres), de modo que el problema —la dificultad de sostenibilidad financiera— no se evidencia; el propio texto señala que la oferta gratuita «no permite afirmar» dificultades financieras. Faltan causas y consecuencias. Los datos de estratos se repiten tres veces (Introducción, Contexto y Justificación). Patio Bonito se denomina indistintamente «barrio», «UPZ» y «localidad».
A22: G3 | B22: Pregunta problema | C22: =Calificación!G40 -> 5 | D22: =IF(C22>=Rúbrica!$D$6,"Logrado","No logrado") -> Logrado | E22: Interrogante descriptivo, único, con objeto, población, lugar y periodo bien delimitados. «En función de las condiciones socioeconómicas» obliga a definir cómo se medirá esa variable.
A23: G3 | B23: Objetivo general | C23: =Calificación!G41 -> 5 | D23: =IF(C23>=Rúbrica!$D$6,"Logrado","No logrado") -> Logrado | E23: Verbo «caracterizar», un propósito, contexto y periodo completos, y concordante con la pregunta. No incluye «crecimiento institucional», que sí se desarrolla en antecedentes y marco teórico.
A24: G3 | B24: Objetivos específicos | C24: =Calificación!G42 -> 3.375 | D24: =IF(C24>=Rúbrica!$D$6,"Logrado","No logrado") -> Logrado | E24: OE1 (identificar) es medible y acotado. OE2 combina tres objetos (estrategias, condiciones socioeconómicas y factores asociados a la sostenibilidad) y exige un análisis relacional que la pregunta descriptiva no contempla. OE3 (proponer lineamientos) es de nivel proyectivo y no está contenido en el objetivo general.
A25: G3 | B25: Justificación | C25: =Calificación!G43 -> 4.375 | D25: =IF(C25>=Rúbrica!$D$6,"Logrado","No logrado") -> Logrado | E25: Desarrolla las perspectivas académica, social y práctica con fuentes (Pachau Torres et al., 2026; Secretaría Distrital de Planeación, 2024; Altamar Bruno et al., 2020). Incluye la limitación de no generalizar. No expone viabilidad (acceso a las escuelas, número de unidades, instrumentos). Extensa (cinco párrafos) y con reiteración del párrafo social sobre la oferta gratuita.
A26: G3 | B26: Antecedentes (Capítulo 2) | C26: =Calificación!G44 -> 4.25 | D26: =IF(C26>=Rúbrica!$D$6,"Logrado","No logrado") -> Logrado | E26: Tres niveles, con síntesis de tendencias y brecha (modelo del curso). Los estudios incluyen objetivo, método y resultado. Limitaciones: tres de los siete estudios nacionales y locales son trabajos de grado o planes de negocio; el antecedente de Mora Poveda (2021) es de formación musical, no deportiva; un antecedente local se cita como «MetaFlip, s/f» (nombre de un visor de repositorio, no el autor). La cita de Rodríguez Castiblanco y Pérez Cortes (2019) remite a una entrada de referencia sin autores.
A27: G3 | B27: Marco teórico y conceptual (Capítulo 2) | C27: =Calificación!G45 -> 1.875 | D27: =IF(C27>=Rúbrica!$D$6,"Logrado","No logrado") -> No logrado | E27: Cinco conceptos con definiciones de dos a tres líneas; tres sin fuente (estrategias de marketing, crecimiento institucional, escuelas de formación) y dos sustentadas solo en Gutiérrez Montaña (2008), que no aparece en la lista de referencias. No hay marco teórico: Fullerton y Merz (2008), citados en la Introducción, no se retoman. No se definen variables ni dimensiones medibles de sostenibilidad financiera o de condiciones socioeconómicas (por ejemplo, estrato). Al final del apartado quedan dos citas sueltas («(Informe de Gestión a diciembre | IDRD…, s/f)» y «(Rodríguez, 2015)») sin texto asociado.
A28: G3 | B28: APA 7 y redacción (transversal) | C28: =Calificación!G46 -> 1.125 | D28: =IF(C28>=Rúbrica!$D$6,"Logrado","No logrado") -> No logrado | E28: Uso sistemático de paréntesis en citas narrativas: «(Fullerton & Merz, 2008) plantean», «(Torres et al., 2026), mediante…», «(Calahorro-López y Ratkai (2024)», «(Ministerio del Deporte, 2024.)», «((Instituto Distrital… [IDRD], 2026)». La misma fuente se cita como «Torres et al., 2026» y «Pachau Torres et al., 2026» y figura dos veces en la lista (una con autores repetidos). 11 de 20 citas no se localizan por autor-año porque las referencias están escritas con el título de la página como autor («Vista de Los clubes de fútbol europeos…», «Parque Patio Bonito | IDRD…», «MetaFlip», «3._diagnostico_de_pdl_de_kennedy»). Gutiérrez Montaña (2008) no tiene referencia. Se emplea «s/f» en lugar de «s. f.», se mantiene la marca «utm_source=chatgpt.com» en un enlace y hay títulos en mayúsculas. Quedan en el documento textos de plantilla (Glosario, «Acá va el resumen») y el nombre del asesor con error («Mnedoza»).
A29: G4 | B29: Descripción del problema | C29: =Calificación!H39 -> 2.5 | D29: =IF(C29>=Rúbrica!$D$6,"Logrado","No logrado") -> No logrado | E29: El texto describe la situación local (cruces de horario, canales de difusión, inscripción), pero no distingue los niveles internacional, nacional y local, y los encabezados «¿Qué?», «¿En quiénes?», «¿Dónde?», «¿En qué periodo?» son guion de trabajo sin redactar. La sección «Magnitud» reporta que «entre el 60 % y el 80 % de la población universitaria en Colombia» es inactiva y atribuye la cifra a Sevil Serrano et al. (2017), estudio de autores españoles con 901 participantes cuyo resumen no indica una muestra colombiana (verificado en el resumen de la fuente), y a Ramírez-Vélez et al. (2016); y reporta 48 % a 67 % de barreras «en el contexto universitario colombiano» con Franco-Idárraga et al. (2022), cuya población es de Manizales. No hay ningún dato de la sede (equipos inscritos, partidos perdidos por W, abstención), aunque el texto habla de «alta tasa de abstención» y «constante pérdida de puntos por w». Causas y consecuencias están desarrolladas (individual, operativa, gestión) pero sin respaldo empírico. El problema presupone la respuesta (que las barreras son logísticas) y el vacío solo se formula en Antecedentes. Hay una oración incompleta («La falta de articulación entre sus cargas horarias académicas y la organización del torneo.»).
A30: G4 | B30: Pregunta problema | C30: =Calificación!H40 -> 5 | D30: =IF(C30>=Rúbrica!$D$6,"Logrado","No logrado") -> Logrado | E30: Interrogante único, concreto y con población, escenario y periodo. Es extensa por la enumeración entre paréntesis y por «según su frecuencia e intensidad percibida», que ya define el instrumento. La lista cerrada de cuatro barreras limita la posibilidad de hallar otras.
A31: G4 | B31: Objetivo general | C31: =Calificación!H41 -> 5 | D31: =IF(C31>=Rúbrica!$D$6,"Logrado","No logrado") -> Logrado | E31: Verbo «determinar» medible, con delimitación completa. Duplica la pregunta; no hay inconsistencia, pero la medición de «frecuencia e intensidad percibida» debe definirse en la metodología (que en este documento está sin elaborar).
A32: G4 | B32: Objetivos específicos | C32: =Calificación!H42 -> 3.25 | D32: =IF(C32>=Rúbrica!$D$6,"Logrado","No logrado") -> Logrado | E32: OE1 introduce «hábitos de participación», variable ausente en la pregunta. OE2 y OE3 se solapan (incidencia percibida vs. jerarquización por frecuencia e intensidad). OE4 (proponer estrategias) pertenece a otro nivel (aplicado) y no está en el general.
A33: G4 | B33: Justificación | C33: =Calificación!H43 -> 3.125 | D33: =IF(C33>=Rúbrica!$D$6,"Logrado","No logrado") -> Logrado | E33: Tres líneas (social e institucional, práctica, académica) con destinatarios identificados (coordinación del torneo). Sustento débil: «la literatura científica confirma que la práctica deportiva recreativa… previene el abandono temprano» se respalda con Ramírez-Vélez et al. (2016), estudio sobre barreras percibidas y obesidad abdominal. Redacción en primera persona («nuestra sede», «encontramos»). No se expone viabilidad (acceso a la población, tamaño).
A34: G4 | B34: Antecedentes (Capítulo 2) | C34: =Calificación!H44 -> 3.875 | D34: =IF(C34>=Rúbrica!$D$6,"Logrado","No logrado") -> Logrado | E34: Cinco revisiones sistemáticas (2019 a 2026) resumidas en una tabla y agrupadas por temas, con límites de la evidencia y vacío explícito: el esquema mejor organizado del curso. Limitaciones: todas son revisiones generales de actividad física; no hay estudios sobre torneos internos, deporte universitario o logística, ni nacionales o locales. El estilo es coloquial («algo parecido», «pesaban», «sirve poco»). No se explica la estrategia de selección de las revisiones.
A35: G4 | B35: Marco teórico y conceptual (Capítulo 2) | C35: =Calificación!H45 -> 3.875 | D35: =IF(C35>=Rúbrica!$D$6,"Logrado","No logrado") -> Logrado | E35: Selección teórica pertinente (modelo jerárquico de restricciones del ocio: Crawford et al., 1991; Jackson, 1988) y cuatro subdimensiones operativas. La sección «Logística deportiva y gestión de actividades deportivas» (tres párrafos) no tiene ninguna cita. Algunas fuentes no respaldan lo afirmado: Flórez Saavedra y Herrada Urriago (2021, tesis de Enfermería sobre actividad física) define «barreras logísticas»; Cardona-Mejía y Padierna-Cardona (2021, sobre programas académicos) respalda el estado de las canchas; y la afirmación de que los cruces de horario son «el factor que con mayor frecuencia genera… derrotas por W» se atribuye a dos estudios que no tratan torneos. Redacción en primera persona plural. La subdimensión «trámites de inscripción y equipamiento» incorpora un elemento (equipamiento) que no está en el objetivo.
A36: G4 | B36: APA 7 y redacción (transversal) | C36: =Calificación!H46 -> 2.5 | D36: =IF(C36>=Rúbrica!$D$6,"Logrado","No logrado") -> No logrado | E36: Citas: «(Crawford et al., 1991) & (Jackson, 1988) quienes plantean»; falta el punto final antes de la cita en varios párrafos; Crawford et al. (1991a) se cita con y sin sufijo. Referencias: Crawford et al. (1991a y 1991b) y Sevil Serrano et al. (2017a y 2017b) son entradas idénticas; las listas de autores de Franco-Idárraga et al. (2022) y Sevil Serrano et al. se repiten completas dentro de la misma entrada; Brown, Ferreira Silva, Mella-Norambuena, Pan y Sim aparecen después de Sevil Serrano (rompen el orden alfabético); tesis rotulada «Bachelor thesis, Enfermería» en inglés. Portada con «Kildeman», «Figeroa», «Monografía presentado… título de en»; Metodología y Resultados con texto de plantilla.
A37: G5 | B37: Descripción del problema | C37: =Calificación!I39 -> 2.125 | D37: =IF(C37>=Rúbrica!$D$6,"Logrado","No logrado") -> No logrado | E37: Se organiza en niveles internacional, nacional y local. Los niveles internacional y nacional se construyen con informes institucionales (FIFA, 2023a, 2023b; UEFA, 2019; DIMAYOR, 2026; Federación Colombiana de Fútbol, 2025; Ministerio del Deporte, 2025) que no tienen referencia en la lista, de modo que no son verificables. El nivel local no describe una situación en la sede; solo justifica la elección de la población. No se enuncia el vacío. La sección «A quiénes afecta y qué consecuencias tiene» contiene fragmentos sin sujeto («a nivel académico vemos…»), minúsculas iniciales («bosa porvenir»), primera persona («analizamos»), y atribuye a Martínez Mina (2025) afirmaciones sobre patrocinios y contratos. En «Magnitud» se afirma que «más del 70 % de las marcas… destinan la totalidad de su presupuesto… al fútbol masculino» (Clavijo Vidal y Vidal Cañas, 2021, trabajo de grado) y que las transmisiones han sido «menos del 15 %» citando un reglamento de competencia, que no es fuente de series históricas. Persisten las etiquetas de plantilla «¿Qué?», «¿En quienes?», y se denomina «Facultad de Administración Deportiva» a la Facultad de Medio Ambiente y Recursos Naturales.
A38: G5 | B38: Pregunta problema | C38: =Calificación!I40 -> 3.25 | D38: =IF(C38>=Rúbrica!$D$6,"Logrado","No logrado") -> Logrado | E38: Interrogante único y abierto (¿cuál es la percepción…?). No hay coherencia en la población: la etiqueta «¿En quiénes?» menciona «estudiantes femeninas», la pregunta alude a las estudiantes del proyecto curricular y la Introducción y la Justificación a las «experiencias de las jugadoras». «Influencia» sugiere causalidad que un estudio de percepción no puede establecer, y «visibilidad» no está definida. La percepción de estudiantes tiene escaso valor como evidencia sobre el marketing de una liga si no se justifica su conocimiento del tema.
A39: G5 | B39: Objetivo general | C39: =Calificación!I41 -> 5 | D39: =IF(C39>=Rúbrica!$D$6,"Logrado","No logrado") -> Logrado | E39: Verbo «analizar», un propósito, población, escenario y periodo explícitos; reproduce la pregunta. Su alcance se limita a percepciones y excluye lo que la Introducción y el título anuncian (narrativas de jugadoras).
